Traceback (most recent call last):
  File "/usr/local/anaconda3/envs/eglm03/lib/python3.8/site-packages/jupyter_cache/executors/utils.py", line 51, in single_nb_execution
    executenb(
  File "/usr/local/anaconda3/envs/eglm03/lib/python3.8/site-packages/nbclient/client.py", line 1087, in execute
    return NotebookClient(nb=nb, resources=resources, km=km, **kwargs).execute()
  File "/usr/local/anaconda3/envs/eglm03/lib/python3.8/site-packages/nbclient/util.py", line 74, in wrapped
    return just_run(coro(*args, **kwargs))
  File "/usr/local/anaconda3/envs/eglm03/lib/python3.8/site-packages/nbclient/util.py", line 53, in just_run
    return loop.run_until_complete(coro)
  File "/usr/local/anaconda3/envs/eglm03/lib/python3.8/asyncio/base_events.py", line 616, in run_until_complete
    return future.result()
  File "/usr/local/anaconda3/envs/eglm03/lib/python3.8/site-packages/nbclient/client.py", line 540, in async_execute
    await self.async_execute_cell(
  File "/usr/local/anaconda3/envs/eglm03/lib/python3.8/site-packages/nbclient/client.py", line 832, in async_execute_cell
    self._check_raise_for_error(cell, exec_reply)
  File "/usr/local/anaconda3/envs/eglm03/lib/python3.8/site-packages/nbclient/client.py", line 740, in _check_raise_for_error
    raise CellExecutionError.from_cell_and_msg(cell, exec_reply['content'])
nbclient.exceptions.CellExecutionError: An error occurred while executing the following cell:
------------------
import matlab.engine
eng = matlab.engine.start_matlab()
------------------

[0;31m---------------------------------------------------------------------------[0m
[0;31mModuleNotFoundError[0m                       Traceback (most recent call last)
[0;32m/usr/local/anaconda3/envs/eglm03/lib/python3.8/site-packages/matlab/engine/__init__.py[0m in [0;36m<module>[0;34m[0m
[1;32m     44[0m [0;32mtry[0m[0;34m:[0m[0;34m[0m[0;34m[0m[0m
[0;32m---> 45[0;31m     [0mpythonengine[0m [0;34m=[0m [0mimportlib[0m[0;34m.[0m[0mimport_module[0m[0;34m([0m[0;34m"matlabengineforpython"[0m[0;34m+[0m[0m_PYTHONVERSION[0m[0;34m)[0m[0;34m[0m[0;34m[0m[0m
[0m[1;32m     46[0m [0;32mexcept[0m[0;34m:[0m[0;34m[0m[0;34m[0m[0m

[0;32m/usr/local/anaconda3/envs/eglm03/lib/python3.8/importlib/__init__.py[0m in [0;36mimport_module[0;34m(name, package)[0m
[1;32m    126[0m             [0mlevel[0m [0;34m+=[0m [0;36m1[0m[0;34m[0m[0;34m[0m[0m
[0;32m--> 127[0;31m     [0;32mreturn[0m [0m_bootstrap[0m[0;34m.[0m[0m_gcd_import[0m[0;34m([0m[0mname[0m[0;34m[[0m[0mlevel[0m[0;34m:[0m[0;34m][0m[0;34m,[0m [0mpackage[0m[0;34m,[0m [0mlevel[0m[0;34m)[0m[0;34m[0m[0;34m[0m[0m
[0m[1;32m    128[0m [0;34m[0m[0m

[0;32m/usr/local/anaconda3/envs/eglm03/lib/python3.8/importlib/_bootstrap.py[0m in [0;36m_gcd_import[0;34m(name, package, level)[0m

[0;32m/usr/local/anaconda3/envs/eglm03/lib/python3.8/importlib/_bootstrap.py[0m in [0;36m_find_and_load[0;34m(name, import_)[0m

[0;32m/usr/local/anaconda3/envs/eglm03/lib/python3.8/importlib/_bootstrap.py[0m in [0;36m_find_and_load_unlocked[0;34m(name, import_)[0m

[0;31mModuleNotFoundError[0m: No module named 'matlabengineforpython3_8'

During handling of the above exception, another exception occurred:

[0;31mModuleNotFoundError[0m                       Traceback (most recent call last)
[0;32m/usr/local/anaconda3/envs/eglm03/lib/python3.8/site-packages/matlab/engine/__init__.py[0m in [0;36m<module>[0;34m[0m
[1;32m     62[0m                 [0mos[0m[0;34m.[0m[0madd_dll_directory[0m[0;34m([0m[0m_bin_dir[0m[0;34m)[0m[0;34m[0m[0;34m[0m[0m
[0;32m---> 63[0;31m         [0mpythonengine[0m [0;34m=[0m [0mimportlib[0m[0;34m.[0m[0mimport_module[0m[0;34m([0m[0;34m"matlabengineforpython"[0m[0;34m+[0m[0m_PYTHONVERSION[0m[0;34m)[0m[0;34m[0m[0;34m[0m[0m
[0m[1;32m     64[0m     [0;32mexcept[0m [0mException[0m [0;32mas[0m [0me[0m[0;34m:[0m[0;34m[0m[0;34m[0m[0m

[0;32m/usr/local/anaconda3/envs/eglm03/lib/python3.8/importlib/__init__.py[0m in [0;36mimport_module[0;34m(name, package)[0m
[1;32m    126[0m             [0mlevel[0m [0;34m+=[0m [0;36m1[0m[0;34m[0m[0;34m[0m[0m
[0;32m--> 127[0;31m     [0;32mreturn[0m [0m_bootstrap[0m[0;34m.[0m[0m_gcd_import[0m[0;34m([0m[0mname[0m[0;34m[[0m[0mlevel[0m[0;34m:[0m[0;34m][0m[0;34m,[0m [0mpackage[0m[0;34m,[0m [0mlevel[0m[0;34m)[0m[0;34m[0m[0;34m[0m[0m
[0m[1;32m    128[0m [0;34m[0m[0m

[0;32m/usr/local/anaconda3/envs/eglm03/lib/python3.8/importlib/_bootstrap.py[0m in [0;36m_gcd_import[0;34m(name, package, level)[0m

[0;32m/usr/local/anaconda3/envs/eglm03/lib/python3.8/importlib/_bootstrap.py[0m in [0;36m_find_and_load[0;34m(name, import_)[0m

[0;32m/usr/local/anaconda3/envs/eglm03/lib/python3.8/importlib/_bootstrap.py[0m in [0;36m_find_and_load_unlocked[0;34m(name, import_)[0m

[0;31mModuleNotFoundError[0m: No module named 'matlabengineforpython3_8'

During handling of the above exception, another exception occurred:

[0;31mOSError[0m                                   Traceback (most recent call last)
[0;32m<ipython-input-6-9b17cde1df14>[0m in [0;36m<module>[0;34m[0m
[0;32m----> 1[0;31m [0;32mimport[0m [0mmatlab[0m[0;34m.[0m[0mengine[0m[0;34m[0m[0;34m[0m[0m
[0m[1;32m      2[0m [0meng[0m [0;34m=[0m [0mmatlab[0m[0;34m.[0m[0mengine[0m[0;34m.[0m[0mstart_matlab[0m[0;34m([0m[0;34m)[0m[0;34m[0m[0;34m[0m[0m

[0;32m/usr/local/anaconda3/envs/eglm03/lib/python3.8/site-packages/matlab/engine/__init__.py[0m in [0;36m<module>[0;34m[0m
[1;32m     63[0m         [0mpythonengine[0m [0;34m=[0m [0mimportlib[0m[0;34m.[0m[0mimport_module[0m[0;34m([0m[0;34m"matlabengineforpython"[0m[0;34m+[0m[0m_PYTHONVERSION[0m[0;34m)[0m[0;34m[0m[0;34m[0m[0m
[1;32m     64[0m     [0;32mexcept[0m [0mException[0m [0;32mas[0m [0me[0m[0;34m:[0m[0;34m[0m[0;34m[0m[0m
[0;32m---> 65[0;31m         raise EnvironmentError('Please reinstall MATLAB Engine for Python or contact '
[0m[1;32m     66[0m                                'MathWorks Technical Support for assistance: %s' % e)
[1;32m     67[0m [0;34m[0m[0m

[0;31mOSError[0m: Please reinstall MATLAB Engine for Python or contact MathWorks Technical Support for assistance: No module named 'matlabengineforpython3_8'
OSError: Please reinstall MATLAB Engine for Python or contact MathWorks Technical Support for assistance: No module named 'matlabengineforpython3_8'

